<mujoco model="Wheel">
    <include file="./shared.xml"></include>

    <worldbody>
        <body name="wheel" pos="0 0 0.11" childclass="body">
            <freejoint name="root"/>
            <geom name="body" type="box" fromto="0 0 0 0 0 0.1" size="0.2" rgba="0.0 0.0 1.0 1.0"/>
            <camera name="body" pos="-1 0 0.5" xyaxes="0 -1 0 1 0 2" mode="trackcom"/>
            <body name="caster" pos="0.15 0 -0.06">
                <geom name="caster" type="sphere" size="0.05" rgba="1.0 0.0 0.0 1.0"/>
                <joint name="caster" type="ball"/>
            </body>
            <body name="left_wheel" pos="-0.1 0.21 -0.01">
                <geom name="left_wheel" type="cylinder" fromto="0 0 0 0 0.02 0" size="0.1" rgba="0.0 1.0 0.0 1.0"/>
                <joint name="left_wheel" type="hinge" axis="0 1 0"/>
            </body>
            <body name="right_wheel" pos="-0.1 -0.21 -0.01">
                <geom name="right_wheel" type="cylinder" fromto="0 0 0 0 -0.02 0" size="0.1" rgba="0.0 1.0 0.0 1.0"/>
                <joint name="right_wheel" type="hinge" axis="0 1 0"/>
            </body>
        </body>
    </worldbody>

    <actuator>
        <motor name="left_wheel" joint="left_wheel" gear="5"/>
        <motor name="right_wheel" joint="right_wheel" gear="5"/>
    </actuator>
</mujoco>
